Workbook

Sheet Top 14 Picks
A1: # | B1: Keyword | C1: Vol/mo | D1: KD | E1: CPC (USD) | F1: Intent | G1: Score | H1: Role | I1: Use it for
A2: 1 | B2: golf buggy | C2: =INDEX('Top 200 Scored'!$D$2:$D$201,MATCH($B2,'Top 200 Scored'!$B$2:$B$201,0)) -> 6600 | D2: =INDEX('Top 200 Scored'!$E$2:$E$201,MATCH($B2,'Top 200 Scored'!$B$2:$B$201,0)) -> 17 | E2: =INDEX('Top 200 Scored'!$F$2:$F$201,MATCH($B2,'Top 200 Scored'!$B$2:$B$201,0)) -> 0.39 | F2: =INDEX('Top 200 Scored'!$G$2:$G$201,MATCH($B2,'Top 200 Scored'!$B$2:$B$201,0)) -> Commercial | G2: =INDEX('Top 200 Scored'!$J$2:$J$201,MATCH($B2,'Top 200 Scored'!$B$2:$B$201,0)) -> 3648.348 | H2: Head term | I2: Homepage title tag and H1
A3: 2 | B3: golf buggy for sale | C3: =INDEX('Top 200 Scored'!$D$2:$D$201,MATCH($B3,'Top 200 Scored'!$B$2:$B$201,0)) -> 1900 | D3: =INDEX('Top 200 Scored'!$E$2:$E$201,MATCH($B3,'Top 200 Scored'!$B$2:$B$201,0)) -> 14 | E3: =INDEX('Top 200 Scored'!$F$2:$F$201,MATCH($B3,'Top 200 Scored'!$B$2:$B$201,0)) -> 0.7 | F3: =INDEX('Top 200 Scored'!$G$2:$G$201,MATCH($B3,'Top 200 Scored'!$B$2:$B$201,0)) -> Transactional | G3: =INDEX('Top 200 Scored'!$J$2:$J$201,MATCH($B3,'Top 200 Scored'!$B$2:$B$201,0)) -> 1192.82 | H3: Money keyword | I3: Main "Shop all golf buggies" page
A4: 3 | B4: buggies golf | C4: =INDEX('Top 200 Scored'!$D$2:$D$201,MATCH($B4,'Top 200 Scored'!$B$2:$B$201,0)) -> 2900 | D4: =INDEX('Top 200 Scored'!$E$2:$E$201,MATCH($B4,'Top 200 Scored'!$B$2:$B$201,0)) -> 13 | E4: =INDEX('Top 200 Scored'!$F$2:$F$201,MATCH($B4,'Top 200 Scored'!$B$2:$B$201,0)) -> 0.39 | F4: =INDEX('Top 200 Scored'!$G$2:$G$201,MATCH($B4,'Top 200 Scored'!$B$2:$B$201,0)) -> Informational, Commercial | G4: =INDEX('Top 200 Scored'!$J$2:$J$201,MATCH($B4,'Top 200 Scored'!$B$2:$B$201,0)) -> 1236.27 | H4: Variant | I4: Same page as #1: H2 and meta description (word-order variant)
A5: 4 | B5: golf buggies | C5: =INDEX('Top 200 Scored'!$D$2:$D$201,MATCH($B5,'Top 200 Scored'!$B$2:$B$201,0)) -> 880 | D5: =INDEX('Top 200 Scored'!$E$2:$E$201,MATCH($B5,'Top 200 Scored'!$B$2:$B$201,0)) -> 11 | E5: =INDEX('Top 200 Scored'!$F$2:$F$201,MATCH($B5,'Top 200 Scored'!$B$2:$B$201,0)) -> 0.5 | F5: =INDEX('Top 200 Scored'!$G$2:$G$201,MATCH($B5,'Top 200 Scored'!$B$2:$B$201,0)) -> Commercial | G5: =INDEX('Top 200 Scored'!$J$2:$J$201,MATCH($B5,'Top 200 Scored'!$B$2:$B$201,0)) -> 507.5136 | H5: Variant | I5: Same page as #1: plural in body copy and internal anchors
A6: 5 | B6: electric golf buggy | C6: =INDEX('Top 200 Scored'!$D$2:$D$201,MATCH($B6,'Top 200 Scored'!$B$2:$B$201,0)) -> 1900 | D6: =INDEX('Top 200 Scored'!$E$2:$E$201,MATCH($B6,'Top 200 Scored'!$B$2:$B$201,0)) -> 36 | E6: =INDEX('Top 200 Scored'!$F$2:$F$201,MATCH($B6,'Top 200 Scored'!$B$2:$B$201,0)) -> 0.44 | F6: =INDEX('Top 200 Scored'!$G$2:$G$201,MATCH($B6,'Top 200 Scored'!$B$2:$B$201,0)) -> Informational, Commercial | G6: =INDEX('Top 200 Scored'!$J$2:$J$201,MATCH($B6,'Top 200 Scored'!$B$2:$B$201,0)) -> 578.816 | H6: Category | I6: Own category page: highest volume in the niche, hardest (KD 36)
A7: 6 | B7: electric golf buggy for sale | C7: =INDEX('Top 200 Scored'!$D$2:$D$201,MATCH($B7,'Top 200 Scored'!$B$2:$B$201,0)) -> 390 | D7: =INDEX('Top 200 Scored'!$E$2:$E$201,MATCH($B7,'Top 200 Scored'!$B$2:$B$201,0)) -> 17 | E7: =INDEX('Top 200 Scored'!$F$2:$F$201,MATCH($B7,'Top 200 Scored'!$B$2:$B$201,0)) -> 0.54 | F7: =INDEX('Top 200 Scored'!$G$2:$G$201,MATCH($B7,'Top 200 Scored'!$B$2:$B$201,0)) -> Transactional | G7: =INDEX('Top 200 Scored'!$J$2:$J$201,MATCH($B7,'Top 200 Scored'!$B$2:$B$201,0)) -> 223.353 | H7: Category | I7: Same electric category page: buyer-intent H2
A8: 7 | B8: golf push buggy | C8: =INDEX('Top 200 Scored'!$D$2:$D$201,MATCH($B8,'Top 200 Scored'!$B$2:$B$201,0)) -> 480 | D8: =INDEX('Top 200 Scored'!$E$2:$E$201,MATCH($B8,'Top 200 Scored'!$B$2:$B$201,0)) -> 10 | E8: =INDEX('Top 200 Scored'!$F$2:$F$201,MATCH($B8,'Top 200 Scored'!$B$2:$B$201,0)) -> 0.34 | F8: =INDEX('Top 200 Scored'!$G$2:$G$201,MATCH($B8,'Top 200 Scored'!$B$2:$B$201,0)) -> Commercial | G8: =INDEX('Top 200 Scored'!$J$2:$J$201,MATCH($B8,'Top 200 Scored'!$B$2:$B$201,0)) -> 388.8 | H8: Category | I8: Push buggy category (also "push golf buggy", "golf buggy push")
A9: 8 | B9: golf trolley | C9: =INDEX('Top 200 Scored'!$D$2:$D$201,MATCH($B9,'Top 200 Scored'!$B$2:$B$201,0)) -> 880 | D9: =INDEX('Top 200 Scored'!$E$2:$E$201,MATCH($B9,'Top 200 Scored'!$B$2:$B$201,0)) -> 13 | E9: =INDEX('Top 200 Scored'!$F$2:$F$201,MATCH($B9,'Top 200 Scored'!$B$2:$B$201,0)) -> 0.32 | F9: =INDEX('Top 200 Scored'!$G$2:$G$201,MATCH($B9,'Top 200 Scored'!$B$2:$B$201,0)) -> Commercial | G9: =INDEX('Top 200 Scored'!$J$2:$J$201,MATCH($B9,'Top 200 Scored'!$B$2:$B$201,0)) -> 427.2048 | H9: Category | I9: Same push/electric copy: the term many Aussies use
A10: 9 | B10: remote control golf buggy | C10: =INDEX('Top 200 Scored'!$D$2:$D$201,MATCH($B10,'Top 200 Scored'!$B$2:$B$201,0)) -> 480 | D10: =INDEX('Top 200 Scored'!$E$2:$E$201,MATCH($B10,'Top 200 Scored'!$B$2:$B$201,0)) -> 12 | E10: =INDEX('Top 200 Scored'!$F$2:$F$201,MATCH($B10,'Top 200 Scored'!$B$2:$B$201,0)) -> 0.4 | F10: =INDEX('Top 200 Scored'!$G$2:$G$201,MATCH($B10,'Top 200 Scored'!$B$2:$B$201,0)) -> Commercial | G10: =INDEX('Top 200 Scored'!$J$2:$J$201,MATCH($B10,'Top 200 Scored'!$B$2:$B$201,0)) -> 258.5088 | H10: Category | I10: Remote buggy category (also "electric golf buggy with remote")
A11: 10 | B11: golf buggy sales | C11: =INDEX('Top 200 Scored'!$D$2:$D$201,MATCH($B11,'Top 200 Scored'!$B$2:$B$201,0)) -> 390 | D11: =INDEX('Top 200 Scored'!$E$2:$E$201,MATCH($B11,'Top 200 Scored'!$B$2:$B$201,0)) -> 5 | E11: =INDEX('Top 200 Scored'!$F$2:$F$201,MATCH($B11,'Top 200 Scored'!$B$2:$B$201,0)) -> 0.7 | F11: =INDEX('Top 200 Scored'!$G$2:$G$201,MATCH($B11,'Top 200 Scored'!$B$2:$B$201,0)) -> Transactional | G11: =INDEX('Top 200 Scored'!$J$2:$J$201,MATCH($B11,'Top 200 Scored'!$B$2:$B$201,0)) -> 255.645 | H11: Quick win | I11: Very low KD, buyer intent: use in shop page copy and meta
A12: 11 | B12: golf buggy accessories | C12: =INDEX('Top 200 Scored'!$D$2:$D$201,MATCH($B12,'Top 200 Scored'!$B$2:$B$201,0)) -> 390 | D12: =INDEX('Top 200 Scored'!$E$2:$E$201,MATCH($B12,'Top 200 Scored'!$B$2:$B$201,0)) -> 4 | E12: =INDEX('Top 200 Scored'!$F$2:$F$201,MATCH($B12,'Top 200 Scored'!$B$2:$B$201,0)) -> 0.44 | F12: =INDEX('Top 200 Scored'!$G$2:$G$201,MATCH($B12,'Top 200 Scored'!$B$2:$B$201,0)) -> Commercial | G12: =INDEX('Top 200 Scored'!$J$2:$J$201,MATCH($B12,'Top 200 Scored'!$B$2:$B$201,0)) -> 232.5024 | H12: Quick win | I12: Accessories category: KD 4, upsell revenue
A13: 12 | B13: golf buggy for sale brisbane | C13: =INDEX('Top 200 Scored'!$D$2:$D$201,MATCH($B13,'Top 200 Scored'!$B$2:$B$201,0)) -> 170 | D13: =INDEX('Top 200 Scored'!$E$2:$E$201,MATCH($B13,'Top 200 Scored'!$B$2:$B$201,0)) -> 3 | E13: =INDEX('Top 200 Scored'!$F$2:$F$201,MATCH($B13,'Top 200 Scored'!$B$2:$B$201,0)) -> 0.74 | F13: =INDEX('Top 200 Scored'!$G$2:$G$201,MATCH($B13,'Top 200 Scored'!$B$2:$B$201,0)) -> Transactional | G13: =INDEX('Top 200 Scored'!$J$2:$J$201,MATCH($B13,'Top 200 Scored'!$B$2:$B$201,0)) -> 105.536 | H13: Local | I13: Brisbane/QLD city page (see City Pages sheet)
... A15: 14 | B15: electric golf cart | C15: =INDEX('Top 200 Scored'!$D$2:$D$201,MATCH($B15,'Top 200 Scored'!$B$2:$B$201,0)) -> 720 | D15: =INDEX('Top 200 Scored'!$E$2:$E$201,MATCH($B15,'Top 200 Scored'!$B$2:$B$201,0)) -> 15 | E15: =INDEX('Top 200 Scored'!$F$2:$F$201,MATCH($B15,'Top 200 Scored'!$B$2:$B$201,0)) -> 0.74 | F15: =INDEX('Top 200 Scored'!$G$2:$G$201,MATCH($B15,'Top 200 Scored'!$B$2:$B$201,0)) -> Commercial | G15: =INDEX('Top 200 Scored'!$J$2:$J$201,MATCH($B15,'Top 200 Scored'!$B$2:$B$201,0)) -> 352.512 | H15: Riding carts only | I15: Only if you sell riding golf carts
B17: Yellow rows apply only if you sell riding golf carts. Values pull live from the Top 200 Scored sheet.

Sheet City Pages
A1: City page | B1: Suggested URL | C1: Buggy volume (all variants) | D1: Buggy keywords | E1: Cart volume (all variants) | F1: Best buggy keyword (H1) | G1: Its vol/mo | H1: Its KD | I1: Priority
A2: Brisbane / QLD | B2: /golf-buggies-for-sale/brisbane/ | C2: =SUMIFS('City Keywords'!$D$2:$D$189,'City Keywords'!$A$2:$A$189,$A2,'City Keywords'!$C$2:$C$189,"Buggy") -> 780 | D2: =COUNTIFS('City Keywords'!$A$2:$A$189,$A2,'City Keywords'!$C$2:$C$189,"Buggy") -> 19 | E2: =SUMIFS('City Keywords'!$D$2:$D$189,'City Keywords'!$A$2:$A$189,$A2,'City Keywords'!$C$2:$C$189,"Cart") -> 1150 | F2: golf buggy for sale brisbane | G2: =IFERROR(INDEX('City Keywords'!$D$2:$D$189,MATCH($F2,'City Keywords'!$B$2:$B$189,0)),0) -> 170 | H2: =IFERROR(INDEX('City Keywords'!$E$2:$E$189,MATCH($F2,'City Keywords'!$B$2:$B$189,0)),"") -> 3 | I2: =IF(C2>=500,"Build first",IF(C2>=200,"Build next","Only if you serve it")) -> Build first
A3: Sydney / NSW | B3: /golf-buggies-for-sale/sydney/ | C3: =SUMIFS('City Keywords'!$D$2:$D$189,'City Keywords'!$A$2:$A$189,$A3,'City Keywords'!$C$2:$C$189,"Buggy") -> 520 | D3: =COUNTIFS('City Keywords'!$A$2:$A$189,$A3,'City Keywords'!$C$2:$C$189,"Buggy") -> 11 | E3: =SUMIFS('City Keywords'!$D$2:$D$189,'City Keywords'!$A$2:$A$189,$A3,'City Keywords'!$C$2:$C$189,"Cart") -> 740 | F3: golf buggies for sale nsw | G3: =IFERROR(INDEX('City Keywords'!$D$2:$D$189,MATCH($F3,'City Keywords'!$B$2:$B$189,0)),0) -> 90 | H3: =IFERROR(INDEX('City Keywords'!$E$2:$E$189,MATCH($F3,'City Keywords'!$B$2:$B$189,0)),"") -> 10 | I3: =IF(C3>=500,"Build first",IF(C3>=200,"Build next","Only if you serve it")) -> Build first
A4: Perth / WA | B4: /golf-buggies-for-sale/perth/ | C4: =SUMIFS('City Keywords'!$D$2:$D$189,'City Keywords'!$A$2:$A$189,$A4,'City Keywords'!$C$2:$C$189,"Buggy") -> 490 | D4: =COUNTIFS('City Keywords'!$A$2:$A$189,$A4,'City Keywords'!$C$2:$C$189,"Buggy") -> 14 | E4: =SUMIFS('City Keywords'!$D$2:$D$189,'City Keywords'!$A$2:$A$189,$A4,'City Keywords'!$C$2:$C$189,"Cart") -> 600 | F4: golf buggy for sale perth | G4: =IFERROR(INDEX('City Keywords'!$D$2:$D$189,MATCH($F4,'City Keywords'!$B$2:$B$189,0)),0) -> 90 | H4: =IFERROR(INDEX('City Keywords'!$E$2:$E$189,MATCH($F4,'City Keywords'!$B$2:$B$189,0)),"") -> 0 | I4: =IF(C4>=500,"Build first",IF(C4>=200,"Build next","Only if you serve it")) -> Build next
A5: Melbourne / VIC | B5: /golf-buggies-for-sale/melbourne/ | C5: =SUMIFS('City Keywords'!$D$2:$D$189,'City Keywords'!$A$2:$A$189,$A5,'City Keywords'!$C$2:$C$189,"Buggy") -> 410 | D5: =COUNTIFS('City Keywords'!$A$2:$A$189,$A5,'City Keywords'!$C$2:$C$189,"Buggy") -> 13 | E5: =SUMIFS('City Keywords'!$D$2:$D$189,'City Keywords'!$A$2:$A$189,$A5,'City Keywords'!$C$2:$C$189,"Cart") -> 990 | F5: golf buggies for sale victoria | G5: =IFERROR(INDEX('City Keywords'!$D$2:$D$189,MATCH($F5,'City Keywords'!$B$2:$B$189,0)),0) -> 90 | H5: =IFERROR(INDEX('City Keywords'!$E$2:$E$189,MATCH($F5,'City Keywords'!$B$2:$B$189,0)),"") -> 4 | I5: =IF(C5>=500,"Build first",IF(C5>=200,"Build next","Only if you serve it")) -> Build next
A6: Gold Coast | B6: /golf-buggies-for-sale/gold-coast/ | C6: =SUMIFS('City Keywords'!$D$2:$D$189,'City Keywords'!$A$2:$A$189,$A6,'City Keywords'!$C$2:$C$189,"Buggy") -> 370 | D6: =COUNTIFS('City Keywords'!$A$2:$A$189,$A6,'City Keywords'!$C$2:$C$189,"Buggy") -> 6 | E6: =SUMIFS('City Keywords'!$D$2:$D$189,'City Keywords'!$A$2:$A$189,$A6,'City Keywords'!$C$2:$C$189,"Cart") -> 450 | F6: golf buggies gold coast | G6: =IFERROR(INDEX('City Keywords'!$D$2:$D$189,MATCH($F6,'City Keywords'!$B$2:$B$189,0)),0) -> 110 | H6: =IFERROR(INDEX('City Keywords'!$E$2:$E$189,MATCH($F6,'City Keywords'!$B$2:$B$189,0)),"") -> 5 | I6: =IF(C6>=500,"Build first",IF(C6>=200,"Build next","Only if you serve it")) -> Build next
A7: Adelaide / SA | B7: /golf-buggies-for-sale/adelaide/ | C7: =SUMIFS('City Keywords'!$D$2:$D$189,'City Keywords'!$A$2:$A$189,$A7,'City Keywords'!$C$2:$C$189,"Buggy") -> 200 | D7: =COUNTIFS('City Keywords'!$A$2:$A$189,$A7,'City Keywords'!$C$2:$C$189,"Buggy") -> 8 | E7: =SUMIFS('City Keywords'!$D$2:$D$189,'City Keywords'!$A$2:$A$189,$A7,'City Keywords'!$C$2:$C$189,"Cart") -> 430 | F7: golf buggy for sale adelaide | G7: =IFERROR(INDEX('City Keywords'!$D$2:$D$189,MATCH($F7,'City Keywords'!$B$2:$B$189,0)),0) -> 40 | H7: =IFERROR(INDEX('City Keywords'!$E$2:$E$189,MATCH($F7,'City Keywords'!$B$2:$B$189,0)),"") -> 0 | I7: =IF(C7>=500,"Build first",IF(C7>=200,"Build next","Only if you serve it")) -> Build next
A8: Canberra / ACT | B8: /golf-buggies-for-sale/canberra/ | C8: =SUMIFS('City Keywords'!$D$2:$D$189,'City Keywords'!$A$2:$A$189,$A8,'City Keywords'!$C$2:$C$189,"Buggy") -> 40 | D8: =COUNTIFS('City Keywords'!$A$2:$A$189,$A8,'City Keywords'!$C$2:$C$189,"Buggy") -> 2 | E8: =SUMIFS('City Keywords'!$D$2:$D$189,'City Keywords'!$A$2:$A$189,$A8,'City Keywords'!$C$2:$C$189,"Cart") -> 40 | F8: golf buggy canberra | G8: =IFERROR(INDEX('City Keywords'!$D$2:$D$189,MATCH($F8,'City Keywords'!$B$2:$B$189,0)),0) -> 20 | H8: =IFERROR(INDEX('City Keywords'!$E$2:$E$189,MATCH($F8,'City Keywords'!$B$2:$B$189,0)),"") -> 0 | I8: =IF(C8>=500,"Build first",IF(C8>=200,"Build next","Only if you serve it")) -> Only if you serve it
A9: Tasmania | B9: /golf-buggies-for-sale/tasmania/ | C9: =SUMIFS('City Keywords'!$D$2:$D$189,'City Keywords'!$A$2:$A$189,$A9,'City Keywords'!$C$2:$C$189,"Buggy") -> 40 | D9: =COUNTIFS('City Keywords'!$A$2:$A$189,$A9,'City Keywords'!$C$2:$C$189,"Buggy") -> 2 | E9: =SUMIFS('City Keywords'!$D$2:$D$189,'City Keywords'!$A$2:$A$189,$A9,'City Keywords'!$C$2:$C$189,"Cart") -> 80 | F9: golf buggy for sale tasmania | G9: =IFERROR(INDEX('City Keywords'!$D$2:$D$189,MATCH($F9,'City Keywords'!$B$2:$B$189,0)),0) -> 20 | H9: =IFERROR(INDEX('City Keywords'!$E$2:$E$189,MATCH($F9,'City Keywords'!$B$2:$B$189,0)),"") -> 0 | I9: =IF(C9>=500,"Build first",IF(C9>=200,"Build next","Only if you serve it")) -> Only if you serve it
A10: Darwin / NT | B10: /golf-buggies-for-sale/darwin/ | C10: =SUMIFS('City Keywords'!$D$2:$D$189,'City Keywords'!$A$2:$A$189,$A10,'City Keywords'!$C$2:$C$189,"Buggy") -> 30 | D10: =COUNTIFS('City Keywords'!$A$2:$A$189,$A10,'City Keywords'!$C$2:$C$189,"Buggy") -> 1 | E10: =SUMIFS('City Keywords'!$D$2:$D$189,'City Keywords'!$A$2:$A$189,$A10,'City Keywords'!$C$2:$C$189,"Cart") -> 60 | F10: golf buggy for sale darwin | G10: =IFERROR(INDEX('City Keywords'!$D$2:$D$189,MATCH($F10,'City Keywords'!$B$2:$B$189,0)),0) -> 30 | H10: =IFERROR(INDEX('City Keywords'!$E$2:$E$189,MATCH($F10,'City Keywords'!$B$2:$B$189,0)),"") -> 0 | I10: =IF(C10>=500,"Build first",IF(C10>=200,"Build next","Only if you serve it")) -> Only if you serve it
A12: Total | C12: =SUM(C2:C10) -> 2880 | E12: =SUM(E2:E10) -> 4540
A14: Build a city page only where you deliver or have a presence. Page tiers: 500+ buggy searches = build first, 200+ = build next. Details in the City Keywords sheet (filter by city page).

Sheet Assumptions
A1: Golf buggy keyword shortlist - AU (Semrush export 2026-09-10)
A2: Score = Volume x (1 - KD/100) x Intent weight x Relevance/100. Edit the blue weights below and every score and ranking input recalculates.
A4: Intent | B4: Weight
A5: Transactional | B5: 1
A6: Commercial | B6: 0.9
A7: Informational, Transactional | B7: 0.8
A8: Informational, Commercial | B8: 0.7
A9: Informational | B9: 0.3
A10: Navigational | B10: 0.3
A11: Default (blank intent) | B11: 0.5
A13: Notes and assumptions
A14: 1. Assumes the shop sells golf buggies (push and electric trolleys). In Australia "golf buggy" = push/electric trolley; "golf cart" = riding vehicle. Rows tagged Track = Cart apply only if you also stock riding carts.
A15: 2. Source: your six Semrush AU exports (golf cart/buggy/push buggy seeds), merged and de-duplicated (69,464 unique keywords). For duplicates the highest volume was kept.
A16: 3. Semrush supplies Keyword Difficulty for only ~1,000 of the 69k keywords, so only keywords with a KD value are scored. Volumes are monthly AU searches.
A17: 4. Excluded: competitor/brand terms (MGI, Stinger, Yamaha, EZGO, Clicgear etc.), used/second-hand, parts, auctions, off-topic ("gold buggy", "golf car"), and anything under 50 searches/month.
A18: 5. Intent weights are a judgement call (buyer intent weighted highest); change them above to test other priorities.
A19: 6. City sheets list city-modified buggy/cart keywords with 20+ searches/month. City volumes are small; build a city page only where you deliver or have a presence.

Sheet Top 200 Scored
A1: Rank | B1: Keyword | C1: Track | D1: Volume/mo | E1: KD | F1: CPC (USD) | G1: Intent | H1: Relevance | I1: Intent weight | J1: Score
A2: 1 | B2: golf buggy | C2: Buggy | D2: 6600 | E2: 17 | F2: 0.39 | G2: Commercial | H2: 74 | I2: =IFERROR(VLOOKUP(G2,Assumptions!$A$5:$B$10,2,FALSE()),Assumptions!$B$11) -> 0.9 | J2: =D2*(1-E2/100)*I2*H2/100 -> 3648.348
A3: 2 | B3: golf cart | C3: Cart | D3: 5400 | E3: 20 | F3: 0.75 | G3: Commercial | H3: 79 | I3: =IFERROR(VLOOKUP(G3,Assumptions!$A$5:$B$10,2,FALSE()),Assumptions!$B$11) -> 0.9 | J3: =D3*(1-E3/100)*I3*H3/100 -> 3071.52
A4: 3 | B4: golf carts for sale | C4: Cart | D4: 2400 | E4: 7 | F4: 0.76 | G4: Transactional | H4: 91 | I4: =IFERROR(VLOOKUP(G4,Assumptions!$A$5:$B$10,2,FALSE()),Assumptions!$B$11) -> 1 | J4: =D4*(1-E4/100)*I4*H4/100 -> 2031.12
A5: 4 | B5: buggies golf | C5: Buggy | D5: 2900 | E5: 13 | F5: 0.39 | G5: Informational, Commercial | H5: 70 | I5: =IFERROR(VLOOKUP(G5,Assumptions!$A$5:$B$10,2,FALSE()),Assumptions!$B$11) -> 0.7 | J5: =D5*(1-E5/100)*I5*H5/100 -> 1236.27
A6: 5 | B6: golf buggy for sale | C6: Buggy | D6: 1900 | E6: 14 | F6: 0.7 | G6: Transactional | H6: 73 | I6: =IFERROR(VLOOKUP(G6,Assumptions!$A$5:$B$10,2,FALSE()),Assumptions!$B$11) -> 1 | J6: =D6*(1-E6/100)*I6*H6/100 -> 1192.82
A7: 6 | B7: golf cart for sale | C7: Cart | D7: 1300 | E7: 8 | F7: 0.69 | G7: Transactional | H7: 86 | I7: =IFERROR(VLOOKUP(G7,Assumptions!$A$5:$B$10,2,FALSE()),Assumptions!$B$11) -> 1 | J7: =D7*(1-E7/100)*I7*H7/100 -> 1028.56
A8: 7 | B8: golf carts | C8: Cart | D8: 1300 | E8: 17 | F8: 0.68 | G8: Commercial | H8: 80 | I8: =IFERROR(VLOOKUP(G8,Assumptions!$A$5:$B$10,2,FALSE()),Assumptions!$B$11) -> 0.9 | J8: =D8*(1-E8/100)*I8*H8/100 -> 776.88
A9: 8 | B9: electric golf buggy | C9: Buggy | D9: 1900 | E9: 36 | F9: 0.44 | G9: Informational, Commercial | H9: 68 | I9: =IFERROR(VLOOKUP(G9,Assumptions!$A$5:$B$10,2,FALSE()),Assumptions!$B$11) -> 0.7 | J9: =D9*(1-E9/100)*I9*H9/100 -> 578.816
A10: 9 | B10: golf buggies | C10: Buggy | D10: 880 | E10: 11 | F10: 0.5 | G10: Commercial | H10: 72 | I10: =IFERROR(VLOOKUP(G10,Assumptions!$A$5:$B$10,2,FALSE()),Assumptions!$B$11) -> 0.9 | J10: =D10*(1-E10/100)*I10*H10/100 -> 507.5136
A11: 10 | B11: golf trolley | C11: Buggy | D11: 880 | E11: 13 | F11: 0.32 | G11: Commercial | H11: 62 | I11: =IFERROR(VLOOKUP(G11,Assumptions!$A$5:$B$10,2,FALSE()),Assumptions!$B$11) -> 0.9 | J11: =D11*(1-E11/100)*I11*H11/100 -> 427.2048
A12: 11 | B12: golf push buggy | C12: Buggy | D12: 480 | E12: 10 | F12: 0.34 | G12: Commercial | H12: 100 | I12: =IFERROR(VLOOKUP(G12,Assumptions!$A$5:$B$10,2,FALSE()),Assumptions!$B$11) -> 0.9 | J12: =D12*(1-E12/100)*I12*H12/100 -> 388.8
A13: 12 | B13: electric golf cart | C13: Cart | D13: 720 | E13: 15 | F13: 0.74 | G13: Commercial | H13: 64 | I13: =IFERROR(VLOOKUP(G13,Assumptions!$A$5:$B$10,2,FALSE()),Assumptions!$B$11) -> 0.9 | J13: =D13*(1-E13/100)*I13*H13/100 -> 352.512
... A201: 200 | B201: golf buggies perth | C201: Buggy | D201: 50 | E201: 18 | F201: 0.38 | G201: Commercial | H201: 76 | I201: =IFERROR(VLOOKUP(G201,Assumptions!$A$5:$B$10,2,FALSE()),Assumptions!$B$11) -> 0.9 | J201: =D201*(1-E201/100)*I201*H201/100 -> 28.044

Sheet City Keywords
A1: City page | B1: Keyword | C1: Track | D1: Volume/mo | E1: KD | F1: CPC (USD) | G1: Intent
A2: Adelaide / SA | B2: golf buggy for sale adelaide | C2: Buggy | D2: 40 | F2: 0.63
A3: Adelaide / SA | B3: electric golf buggies adelaide | C3: Buggy | D3: 30 | F3: 0.55
A4: Adelaide / SA | B4: electric golf buggy for sale adelaide | C4: Buggy | D4: 30 | F4: 0.57
A5: Adelaide / SA | B5: electric golf buggy adelaide | C5: Buggy | D5: 20 | F5: 0
A6: Adelaide / SA | B6: golf buggies for sale adelaide | C6: Buggy | D6: 20 | F6: 0.63
A7: Adelaide / SA | B7: golf buggy adelaide | C7: Buggy | D7: 20 | F7: 0.45
A8: Adelaide / SA | B8: golf buggy repairs adelaide | C8: Buggy | D8: 20 | F8: 0
A9: Adelaide / SA | B9: motorised golf buggies adelaide | C9: Buggy | D9: 20 | F9: 0
A10: Adelaide / SA | B10: golf carts for sale adelaide | C10: Cart | D10: 140 | E10: 6 | F10: 0.56 | G10: Transactional
A11: Adelaide / SA | B11: golf carts adelaide | C11: Cart | D11: 50 | E11: 6 | F11: 0.56 | G11: Commercial
A12: Adelaide / SA | B12: golf cart for sale adelaide | C12: Cart | D12: 30 | F12: 0.56
A13: Adelaide / SA | B13: golf carts for sale south australia | C13: Cart | D13: 30 | F13: 0.7
A14: Adelaide / SA | B14: electric golf carts adelaide | C14: Cart | D14: 20 | F14: 0
A15: Adelaide / SA | B15: fairway golf carts adelaide | C15: Cart | D15: 20 | F15: 0
A16: Adelaide / SA | B16: golf cart hire adelaide | C16: Cart | D16: 20 | F16: 0
A17: Adelaide / SA | B17: golf cart sa | C17: Cart | D17: 20 | F17: 1.83
A18: Adelaide / SA | B18: golf cart solutions adelaide | C18: Cart | D18: 20 | F18: 1.12
A19: Adelaide / SA | B19: golf carts for sale sa | C19: Cart | D19: 20 | F19: 0
A20: Adelaide / SA | B20: golf carts south australia | C20: Cart | D20: 20 | F20: 0.43
A21: Adelaide / SA | B21: petrol golf cart for sale south australia | C21: Cart | D21: 20 | F21: 0
A22: Adelaide / SA | B22: sa golf carts | C22: Cart | D22: 20 | F22: 0
A23: Brisbane / QLD | B23: golf buggy for sale brisbane | C23: Buggy | D23: 170 | E23: 3 | F23: 0.74 | G23: Transactional
A24: Brisbane / QLD | B24: golf buggies for sale qld | C24: Buggy | D24: 110 | E24: 12 | F24: 0.67 | G24: Transactional
A25: Brisbane / QLD | B25: golf buggy for sale qld | C25: Buggy | D25: 110 | E25: 8 | F25: 0.71 | G25: Transactional
A26: Brisbane / QLD | B26: golf buggies for sale brisbane | C26: Buggy | D26: 70 | E26: 7 | F26: 0.75 | G26: Transactional
A27: Brisbane / QLD | B27: electric golf buggies brisbane | C27: Buggy | D27: 30 | F27: 0
A28: Brisbane / QLD | B28: golf buggies brisbane | C28: Buggy | D28: 30 | F28: 0.83
A29: Brisbane / QLD | B29: electric golf buggies for sale brisbane | C29: Buggy | D29: 20 | F29: 0
A30: Brisbane / QLD | B30: electric golf buggy brisbane | C30: Buggy | D30: 20 | F30: 0.56
A31: Brisbane / QLD | B31: electric golf buggy for sale qld | C31: Buggy | D31: 20 | F31: 0
A32: Brisbane / QLD | B32: golf buggy batteries brisbane | C32: Buggy | D32: 20 | F32: 0.69
A33: Brisbane / QLD | B33: golf buggy brisbane | C33: Buggy | D33: 20 | F33: 0.54
A34: Brisbane / QLD | B34: golf buggy for sale sunshine coast | C34: Buggy | D34: 20 | F34: 0.44
A35: Brisbane / QLD | B35: golf buggy for sale toowoomba | C35: Buggy | D35: 20 | F35: 0.52
A36: Brisbane / QLD | B36: golf buggy hire brisbane | C36: Buggy | D36: 20 | F36: 0
A37: Brisbane / QLD | B37: golf buggy parts brisbane | C37: Buggy | D37: 20 | F37: 0.34
A38: Brisbane / QLD | B38: golf buggy registration qld | C38: Buggy | D38: 20 | F38: 0
... A41: Brisbane / QLD | B41: petrol golf buggy for sale queensland | C41: Buggy | D41: 20 | F41: 0
A42: Brisbane / QLD | B42: golf carts for sale brisbane | C42: Cart | D42: 210 | E42: 6 | F42: 0.75 | G42: Transactional
...
